2018-12-04 00:01:50,912 ERROR: Exception on /notifications [GET] [in /Users/pankajshere/Projects/microblog/lib/python3.6/site-packages/flask/app.py:1761]
Traceback (most recent call last):
  File "/Users/pankajshere/Projects/microblog/lib/python3.6/site-packages/sqlalchemy/engine/base.py", line 1193, in _execute_context
    context)
  File "/Users/pankajshere/Projects/microblog/lib/python3.6/site-packages/sqlalchemy/engine/default.py", line 509, in do_execute
    cursor.execute(statement, parameters)
sqlite3.OperationalError: database is locked

The above exception was the direct cause of the following exception:

Traceback (most recent call last):
  File "/Users/pankajshere/Projects/microblog/lib/python3.6/site-packages/flask/app.py", line 2292, in wsgi_app
    response = self.full_dispatch_request()
  File "/Users/pankajshere/Projects/microblog/lib/python3.6/site-packages/flask/app.py", line 1815, in full_dispatch_request
    rv = self.handle_user_exception(e)
  File "/Users/pankajshere/Projects/microblog/lib/python3.6/site-packages/flask/app.py", line 1718, in handle_user_exception
    reraise(exc_type, exc_value, tb)
  File "/Users/pankajshere/Projects/microblog/lib/python3.6/site-packages/flask/_compat.py", line 35, in reraise
    raise value
  File "/Users/pankajshere/Projects/microblog/lib/python3.6/site-packages/flask/app.py", line 1811, in full_dispatch_request
    rv = self.preprocess_request()
  File "/Users/pankajshere/Projects/microblog/lib/python3.6/site-packages/flask/app.py", line 2087, in preprocess_request
    rv = func()
  File "/Users/pankajshere/Projects/microblog/app/main/routes.py", line 60, in before_request
    db.session.commit()
  File "/Users/pankajshere/Projects/microblog/lib/python3.6/site-packages/sqlalchemy/orm/scoping.py", line 153, in do
    return getattr(self.registry(), name)(*args, **kwargs)
  File "/Users/pankajshere/Projects/microblog/lib/python3.6/site-packages/sqlalchemy/orm/session.py", line 954, in commit
    self.transaction.commit()
  File "/Users/pankajshere/Projects/microblog/lib/python3.6/site-packages/sqlalchemy/orm/session.py", line 467, in commit
    self._prepare_impl()
  File "/Users/pankajshere/Projects/microblog/lib/python3.6/site-packages/sqlalchemy/orm/session.py", line 447, in _prepare_impl
    self.session.flush()
  File "/Users/pankajshere/Projects/microblog/lib/python3.6/site-packages/sqlalchemy/orm/session.py", line 2313, in flush
    self._flush(objects)
  File "/Users/pankajshere/Projects/microblog/lib/python3.6/site-packages/sqlalchemy/orm/session.py", line 2440, in _flush
    transaction.rollback(_capture_exception=True)
  File "/Users/pankajshere/Projects/microblog/lib/python3.6/site-packages/sqlalchemy/util/langhelpers.py", line 66, in __exit__
    compat.reraise(exc_type, exc_value, exc_tb)
  File "/Users/pankajshere/Projects/microblog/lib/python3.6/site-packages/sqlalchemy/util/compat.py", line 249, in reraise
    raise value
  File "/Users/pankajshere/Projects/microblog/lib/python3.6/site-packages/sqlalchemy/orm/session.py", line 2404, in _flush
    flush_context.execute()
  File "/Users/pankajshere/Projects/microblog/lib/python3.6/site-packages/sqlalchemy/orm/unitofwork.py", line 395, in execute
    rec.execute(self)
  File "/Users/pankajshere/Projects/microblog/lib/python3.6/site-packages/sqlalchemy/orm/unitofwork.py", line 560, in execute
    uow
  File "/Users/pankajshere/Projects/microblog/lib/python3.6/site-packages/sqlalchemy/orm/persistence.py", line 177, in save_obj
    mapper, table, update)
  File "/Users/pankajshere/Projects/microblog/lib/python3.6/site-packages/sqlalchemy/orm/persistence.py", line 774, in _emit_update_statements
    execute(statement, multiparams)
  File "/Users/pankajshere/Projects/microblog/lib/python3.6/site-packages/sqlalchemy/engine/base.py", line 948, in execute
    return meth(self, multiparams, params)
  File "/Users/pankajshere/Projects/microblog/lib/python3.6/site-packages/sqlalchemy/sql/elements.py", line 269, in _execute_on_connection
    return connection._execute_clauseelement(self, multiparams, params)
  File "/Users/pankajshere/Projects/microblog/lib/python3.6/site-packages/sqlalchemy/engine/base.py", line 1060, in _execute_clauseelement
    compiled_sql, distilled_params
  File "/Users/pankajshere/Projects/microblog/lib/python3.6/site-packages/sqlalchemy/engine/base.py", line 1200, in _execute_context
    context)
  File "/Users/pankajshere/Projects/microblog/lib/python3.6/site-packages/sqlalchemy/engine/base.py", line 1413, in _handle_dbapi_exception
    exc_info
  File "/Users/pankajshere/Projects/microblog/lib/python3.6/site-packages/sqlalchemy/util/compat.py", line 265, in raise_from_cause
    reraise(type(exception), exception, tb=exc_tb, cause=cause)
  File "/Users/pankajshere/Projects/microblog/lib/python3.6/site-packages/sqlalchemy/util/compat.py", line 248, in reraise
    raise value.with_traceback(tb)
  File "/Users/pankajshere/Projects/microblog/lib/python3.6/site-packages/sqlalchemy/engine/base.py", line 1193, in _execute_context
    context)
  File "/Users/pankajshere/Projects/microblog/lib/python3.6/site-packages/sqlalchemy/engine/default.py", line 509, in do_execute
    cursor.execute(statement, parameters)
sqlalchemy.exc.OperationalError: (sqlite3.OperationalError) database is locked [SQL: 'UPDATE user SET last_seen=? WHERE user.id = ?'] [parameters: ('2018-12-03 18:31:45.680001', 2)] (Background on this error at: http://sqlalche.me/e/e3q8)
2018-12-04 00:03:03,607 INFO: Microblog startup [in /Users/pankajshere/Projects/microblog/app/__init__.py:85]
2018-12-04 00:37:15,986 INFO: Microblog startup [in /Users/pankajshere/Projects/microblog/app/__init__.py:85]
2018-12-04 00:38:21,761 INFO: Microblog startup [in ./app/__init__.py:85]
2018-12-04 00:50:05,521 INFO: Microblog startup [in /Users/pankajshere/Projects/microblog/app/__init__.py:85]
2018-12-04 00:50:23,393 INFO: Microblog startup [in ./app/__init__.py:85]
2018-12-04 01:13:44,467 INFO: Microblog startup [in /Users/pankajshere/Projects/microblog/app/__init__.py:85]
2018-12-04 01:13:54,437 INFO: Microblog startup [in /Users/pankajshere/Projects/microblog/app/__init__.py:85]
2018-12-04 01:14:13,083 INFO: Microblog startup [in /Users/pankajshere/Projects/microblog/app/__init__.py:85]
2018-12-04 01:14:30,875 INFO: Microblog startup [in ./app/__init__.py:85]
2018-12-05 23:38:11,448 INFO: Microblog startup [in /Users/pankajshere/Projects/microblog/app/__init__.py:85]
2018-12-06 00:57:22,310 INFO: Microblog startup [in /Users/pankajshere/Projects/microblog/app/__init__.py:89]
2018-12-06 01:11:34,469 INFO: Microblog startup [in /Users/pankajshere/Projects/microblog/app/__init__.py:89]
2018-12-06 01:14:40,031 INFO: Microblog startup [in /Users/pankajshere/Projects/microblog/app/__init__.py:89]
2018-12-06 01:26:41,532 INFO: Microblog startup [in /Users/pankajshere/Projects/microblog/app/__init__.py:89]
2018-12-06 01:29:14,502 INFO: Microblog startup [in /Users/pankajshere/Projects/microblog/app/__init__.py:89]
2018-12-06 01:30:34,692 INFO: Microblog startup [in /Users/pankajshere/Projects/microblog/app/__init__.py:89]
2018-12-06 01:37:50,946 INFO: Microblog startup [in /Users/pankajshere/Projects/microblog/app/__init__.py:89]
2018-12-06 01:38:47,561 ERROR: Exception on /api/users/1 [GET] [in /Users/pankajshere/Projects/microblog/lib/python3.6/site-packages/flask/app.py:1761]
Traceback (most recent call last):
  File "/Users/pankajshere/Projects/microblog/lib/python3.6/site-packages/flask/app.py", line 2292, in wsgi_app
    response = self.full_dispatch_request()
  File "/Users/pankajshere/Projects/microblog/lib/python3.6/site-packages/flask/app.py", line 1815, in full_dispatch_request
    rv = self.handle_user_exception(e)
  File "/Users/pankajshere/Projects/microblog/lib/python3.6/site-packages/flask/app.py", line 1718, in handle_user_exception
    reraise(exc_type, exc_value, tb)
  File "/Users/pankajshere/Projects/microblog/lib/python3.6/site-packages/flask/_compat.py", line 35, in reraise
    raise value
  File "/Users/pankajshere/Projects/microblog/lib/python3.6/site-packages/flask/app.py", line 1813, in full_dispatch_request
    rv = self.dispatch_request()
  File "/Users/pankajshere/Projects/microblog/lib/python3.6/site-packages/flask/app.py", line 1799, in dispatch_request
    return self.view_functions[rule.endpoint](**req.view_args)
  File "/Users/pankajshere/Projects/microblog/app/api/users.py", line 8, in get_user
    return jsonify(User.query.get_or_404(id).to_dict())
  File "/Users/pankajshere/Projects/microblog/app/models.py", line 191, in to_dict
    'post_count': self.posts_count(),
AttributeError: 'User' object has no attribute 'posts_count'
2018-12-06 01:41:19,674 INFO: Microblog startup [in /Users/pankajshere/Projects/microblog/app/__init__.py:89]
2018-12-06 01:55:59,505 INFO: Microblog startup [in /Users/pankajshere/Projects/microblog/app/__init__.py:89]
2018-12-06 12:34:13,975 INFO: Microblog startup [in /Users/pankajshere/Projects/microblog/app/__init__.py:89]
2018-12-06 12:52:46,345 INFO: Microblog startup [in /Users/pankajshere/Projects/microblog/app/__init__.py:89]
2018-12-06 12:55:57,670 ERROR: Exception on /api/users/2 [PUT] [in /Users/pankajshere/Projects/microblog/lib/python3.6/site-packages/flask/app.py:1761]
Traceback (most recent call last):
  File "/Users/pankajshere/Projects/microblog/lib/python3.6/site-packages/flask/app.py", line 2292, in wsgi_app
    response = self.full_dispatch_request()
  File "/Users/pankajshere/Projects/microblog/lib/python3.6/site-packages/flask/app.py", line 1816, in full_dispatch_request
    return self.finalize_request(rv)
  File "/Users/pankajshere/Projects/microblog/lib/python3.6/site-packages/flask/app.py", line 1831, in finalize_request
    response = self.make_response(rv)
  File "/Users/pankajshere/Projects/microblog/lib/python3.6/site-packages/flask/app.py", line 1957, in make_response
    'The view function did not return a valid response. The'
TypeError: The view function did not return a valid response. The function either returned None or ended without a return statement.
